Workbook

Sheet 【データ入力】
B2: 【データ入力】 | D2: 予算： | E2: 2018年度 | G2: 実績： | H2: 2018年度
B3: ※下表の色付きセルに入力ください
B4: ●2018年度予算 | N4: 単位： 千円 | U4: 単位： 千円
C5: 1Q | F5: 2Q | I5: 3Q | L5: 4Q | O5: 1Q | P5: 2Q | Q5: 3Q | R5: 4Q | S5: 上期 | T5: 下期 | U5: 合計
C6: 4 | D6: 5 | E6: 6 | F6: 7 | G6: 8 | H6: 9 | I6: 10 | J6: 11 | K6: 12 | L6: 1 | M6: 2 | N6: 3
B7: 売上高実績 | C7: =+実績見込予算!E31 -> 483343.02 | D7: =+実績見込予算!F31 -> 506279.1 | E7: =+実績見込予算!G31 -> 497007.37 | F7: =+実績見込予算!H31 -> 520531.62 | G7: =+実績見込予算!I31 -> 514603.67 | H7: =+実績見込予算!J31 -> 524026.53 | I7: =+実績見込予算!K31 -> 525588.47 | J7: =+実績見込予算!L31 -> 529321.78 | ... N7: =+実績見込予算!P31 -> 513607.89 | O7: =SUM(C7:E7) -> 1486629.5 | P7: =SUM(F7:H7) -> 1559161.8 | Q7: =SUM(I7:K7) -> 1576212.2 | R7: =SUM(L7:N7) -> 1539159.3 | S7: =SUM(O7:P7) -> 3045791.3 | T7: =SUM(Q7:R7) -> 3115371.4 | U7: =SUM(S7:T7) -> 6161162.7
B8: 営業利益実績 | C8: =+実績見込予算!E33 -> 74732.749 | D8: =+実績見込予算!F33 -> 89548.246 | E8: =+実績見込予算!G33 -> 75910.724 | F8: =+実績見込予算!H33 -> 103820.92 | G8: =+実績見込予算!I33 -> 100143.84 | H8: =+実績見込予算!J33 -> 100964.33 | I8: =+実績見込予算!K33 -> 106665.23 | J8: =+実績見込予算!L33 -> 109866.55 | ... N8: =+実績見込予算!P33 -> 103862.5 | O8: =SUM(C8:E8) -> 240191.72 | P8: =SUM(F8:H8) -> 304929.09 | Q8: =SUM(I8:K8) -> 318300.52 | R8: =SUM(L8:N8) -> 311792.18 | S8: =SUM(O8:P8) -> 545120.81 | T8: =SUM(Q8:R8) -> 630092.7 | U8: =SUM(S8:T8) -> 1175213.5
B9: 営業利益率 | C9: =SUM(C8/C7) -> 0.15461638 | D9: =SUM(D8/D7) -> 0.17687526 | E9: =SUM(E8/E7) -> 0.15273561 | F9: =SUM(F8/F7) -> 0.1994517 | G9: =SUM(G8/G7) -> 0.19460382 | H9: =SUM(H8/H7) -> 0.19267027 | I9: =SUM(I8/I7) -> 0.20294438 | J9: =SUM(J8/J7) -> 0.20756099 | ... U9: =SUM(U8/U7) -> 0.19074541
B12: ●2018年度実・見込 | N12: 単位： 千円 | U12: 単位： 千円
C13: 1Q | F13: 2Q | I13: 3Q | L13: 4Q | O13: 1Q | P13: 2Q | Q13: 3Q | R13: 4Q | S13: 上期 | T13: 下期 | U13: 合計
C14: 4 | D14: 5 | E14: 6 | F14: 7 | G14: 8 | H14: 9 | I14: 10 | J14: 11 | K14: 12 | L14: 1 | M14: 2 | N14: 3
B15: 売上高予算 | C15: =+実績見込予算!E32 -> 499841.72 | D15: =+実績見込予算!F32 -> 504945.39 | E15: =+実績見込予算!G32 -> 507247.43 | F15: =+実績見込予算!H32 -> 555489.46 | G15: =+実績見込予算!I32 -> 548441.69 | H15: =+実績見込予算!J32 -> 582096.89 | I15: =+実績見込予算!K32 -> 619845.7 | J15: =+実績見込予算!L32 -> 622891.62 | ... N15: =+実績見込予算!P32 -> 592948.2 | O15: =SUM(C15:E15) -> 1512034.5 | P15: =SUM(F15:H15) -> 1686028 | Q15: =SUM(I15:K15) -> 1860845.4 | R15: =SUM(L15:N15) -> 1781406.2 | S15: =SUM(O15:P15) -> 3198062.6 | T15: =SUM(Q15:R15) -> 3642251.6 | U15: =SUM(S15:T15) -> 6840314.2
B16: 営業利益予算 | C16: =+実績見込予算!E34 -> 75435.085 | D16: =+実績見込予算!F34 -> 78912.892 | E16: =+実績見込予算!G34 -> 85485.532 | F16: =+実績見込予算!H34 -> 99301.796 | G16: =+実績見込予算!I34 -> 101020.88 | H16: =+実績見込予算!J34 -> 100859.21 | I16: =+実績見込予算!K34 -> 128299.75 | J16: =+実績見込予算!L34 -> 126624.21 | ... N16: =+実績見込予算!P34 -> 121819.01 | O16: =SUM(C16:E16) -> 239833.51 | P16: =SUM(F16:H16) -> 301181.88 | Q16: =SUM(I16:K16) -> 379863.37 | R16: =SUM(L16:N16) -> 356569.04 | S16: =SUM(O16:P16) -> 541015.39 | T16: =SUM(Q16:R16) -> 736432.41 | U16: =SUM(S16:T16) -> 1277447.8
B17: 営業利益率（予算） | C17: =SUM(C16/C15) -> 0.15091794 | D17: =SUM(D16/D15) -> 0.15628005 | E17: =SUM(E16/E15) -> 0.16852827 | F17: =SUM(F16/F15) -> 0.1787645 | G17: =SUM(G16/G15) -> 0.18419621 | H17: =SUM(H16/H15) -> 0.17326877 | I17: =SUM(I16/I15) -> 0.20698659 | J17: =SUM(J16/J15) -> 0.20328449 | ... U17: =SUM(U16/U15) -> 0.1867528
B19: ↓上記グラフからの自動リンク / 発表書式への自動リンク
B20: 【グラフ用（自動入力）】
B22: =B4 -> ●2018年度予算 | C22: 予算 | U22: 単位： 百万円
C23: 1Q | F23: 2Q | I23: 3Q | L23: 4Q | O23: 1Q | P23: 2Q | Q23: 3Q | R23: 4Q | S23: 上期 | T23: 下期 | U23: 合計
C24: 4 | D24: 5 | E24: 6 | F24: 7 | G24: 8 | H24: 9 | I24: 10 | J24: 11 | K24: 12 | L24: 1 | M24: 2 | N24: 3
B25: =B7 -> 売上高実績 | C25: =C7/1000 -> 483.34302 | D25: =D7/1000 -> 506.2791 | E25: =E7/1000 -> 497.00737 | F25: =F7/1000 -> 520.53162 | G25: =G7/1000 -> 514.60367 | H25: =H7/1000 -> 524.02653 | I25: =I7/1000 -> 525.58847 | J25: =J7/1000 -> 529.32178 | ... N25: =N7/1000 -> 513.60789 | O25: =SUM(C25:E25) -> 1486.6295 | P25: =SUM(F25:H25) -> 1559.1618 | Q25: =SUM(I25:K25) -> 1576.2122 | R25: =SUM(L25:N25) -> 1539.1593 | S25: =SUM(O25:P25) -> 3045.7913 | T25: =SUM(Q25:R25) -> 3115.3714 | U25: =SUM(S25:T25) -> 6161.1627
B26: =B8 -> 営業利益実績 | C26: =C8/1000 -> 74.732749 | D26: =D8/1000 -> 89.548246 | E26: =E8/1000 -> 75.910724 | F26: =F8/1000 -> 103.82092 | G26: =G8/1000 -> 100.14384 | H26: =H8/1000 -> 100.96433 | I26: =I8/1000 -> 106.66523 | J26: =J8/1000 -> 109.86655 | ... N26: =N8/1000 -> 103.8625 | O26: =SUM(C26:E26) -> 240.19172 | P26: =SUM(F26:H26) -> 304.92909 | Q26: =SUM(I26:K26) -> 318.30052 | R26: =SUM(L26:N26) -> 311.79218 | S26: =SUM(O26:P26) -> 545.12081 | T26: =SUM(Q26:R26) -> 630.0927 | U26: =SUM(S26:T26) -> 1175.2135
B27: =B9 -> 営業利益率 | C27: =C26/C25 -> 0.15461638 | D27: =D26/D25 -> 0.17687526 | E27: =E26/E25 -> 0.15273561 | F27: =F26/F25 -> 0.1994517 | G27: =G26/G25 -> 0.19460382 | H27: =H26/H25 -> 0.19267027 | I27: =I26/I25 -> 0.20294438 | J27: =J26/J25 -> 0.20756099 | ... N27: =N26/N25 -> 0.2022214 | O27: =+O26/O25 -> 0.16156798 | P27: =+P26/P25 -> 0.19557245 | Q27: =+Q26/Q25 -> 0.20194015 | R27: =+R26/R25 -> 0.20257304 | S27: =+S26/S25 -> 0.1789751 | T27: =+T26/T25 -> 0.20225283 | U27: =+U26/U25 -> 0.19074541
B30: =B12 -> ●2018年度実・見込 | C30: 実・見込 | U30: 単位： 百万円
C31: 1Q | F31: 2Q | I31: 3Q | L31: 4Q | O31: 1Q | P31: 2Q | Q31: 3Q | R31: 4Q | S31: 上期 | T31: 下期 | U31: 合計
C32: 4 | D32: 5 | E32: 6 | F32: 7 | G32: 8 | H32: 9 | I32: 10 | J32: 11 | K32: 12 | L32: 1 | M32: 2 | N32: 3
B33: =B15 -> 売上高予算 | C33: =C15/1000 -> 499.84172 | D33: =D15/1000 -> 504.94539 | E33: =E15/1000 -> 507.24743 | F33: =F15/1000 -> 555.48946 | G33: =G15/1000 -> 548.44169 | H33: =H15/1000 -> 582.09689 | I33: =I15/1000 -> 619.8457 | J33: =J15/1000 -> 622.89162 | ... N33: =N15/1000 -> 592.9482 | O33: =SUM(C33:E33) -> 1512.0345 | P33: =SUM(F33:H33) -> 1686.028 | Q33: =SUM(I33:K33) -> 1860.8454 | R33: =SUM(L33:N33) -> 1781.4062 | S33: =SUM(O33:P33) -> 3198.0626 | T33: =SUM(Q33:R33) -> 3642.2516 | U33: =SUM(S33:T33) -> 6840.3142
B34: =B16 -> 営業利益予算 | C34: =C16/1000 -> 75.435085 | D34: =D16/1000 -> 78.912892 | E34: =E16/1000 -> 85.485532 | F34: =F16/1000 -> 99.301796 | G34: =G16/1000 -> 101.02088 | H34: =H16/1000 -> 100.85921 | I34: =I16/1000 -> 128.29975 | J34: =J16/1000 -> 126.62421 | ... N34: =N16/1000 -> 121.81901 | O34: =SUM(C34:E34) -> 239.83351 | P34: =SUM(F34:H34) -> 301.18188 | Q34: =SUM(I34:K34) -> 379.86337 | R34: =SUM(L34:N34) -> 356.56904 | S34: =SUM(O34:P34) -> 541.01539 | T34: =SUM(Q34:R34) -> 736.43241 | U34: =SUM(S34:T34) -> 1277.4478
B35: =B17 -> 営業利益率（予算） | C35: =C34/C33 -> 0.15091794 | D35: =D34/D33 -> 0.15628005 | E35: =E34/E33 -> 0.16852827 | F35: =F34/F33 -> 0.1787645 | G35: =G34/G33 -> 0.18419621 | H35: =H34/H33 -> 0.17326877 | I35: =I34/I33 -> 0.20698659 | J35: =J34/J33 -> 0.20328449 | ... U35: =U34/U33 -> 0.1867528

Sheet 発表書式
C2: 部署名をご記載ください | P2: 実績： | Q2: =【データ入力】!H2 -> 2018年度 | U2: 予算： | V2: =【データ入力】!E2 -> 2018年度
C3: ■ 売上/利益 | AA3: 単位：百万円
Q4: 1Q | S4: 2Q | U4: 3Q | W4: 4Q | Y4: 通期 | AA4: 達成率/成長率
N5: 売上高 | O5: 2015 | P5: 実績 | Q5: =【データ入力】!O25 -> 1486.6295 | S5: =【データ入力】!P25 -> 1559.1618 | U5: =【データ入力】!Q25 -> 1576.2122 | W5: =【データ入力】!R25 -> 1539.1593 | Y5: =【データ入力】!U25 -> 6161.1627 | AA5: =【データ入力】!U25/【データ入力】!#REF! -> #REF!
O6: 2016 | P6: 予算 | Q6: =【データ入力】!O33 -> 1512.0345 | S6: =【データ入力】!P33 -> 1686.028 | U6: =【データ入力】!Q33 -> 1860.8454 | W6: =【データ入力】!R33 -> 1781.4062 | Y6: =【データ入力】!U33 -> 6840.3142
P7: 前期比 | Q7: =Q6/Q5 -> 1.017089 | S7: =SUM(【データ入力】!F33:H33) -> 1686.028 | U7: =SUM(【データ入力】!I33:K33) -> 1860.8454 | W7: =SUM(【データ入力】!L33:N33) -> 1781.4062 | Y7: =【データ入力】!U33 -> 6840.3142
N8: 営業利益 | O8: 2015 | P8: 実績 | Q8: =【データ入力】!O26 -> 240.19172 | S8: =【データ入力】!P26 -> 304.92909 | U8: =【データ入力】!Q26 -> 318.30052 | W8: =【データ入力】!R26 -> 311.79218 | Y8: =【データ入力】!U26 -> 1175.2135 | AA8: =【データ入力】!U26/【データ入力】!#REF! -> #REF!
O9: 2016 | P9: 予算 | Q9: =【データ入力】!O34 -> 239.83351 | S9: =【データ入力】!P34 -> 301.18188 | U9: =【データ入力】!Q34 -> 379.86337 | W9: =【データ入力】!R34 -> 356.56904 | Y9: =【データ入力】!U34 -> 1277.4478
P10: 前期比 | Q10: =Q9/Q8 -> 0.99850865 | S10: =S9/S8 -> 0.98771122 | U10: =U9/U8 -> 1.1934111 | W10: =W9/W8 -> 1.1436113 | Y10: =Y9/Y8 -> 1.0869921
N11: 営業 利益率 | O11: 2015 | P11: 実績 | Q11: =Q8/Q5 -> 0.16156798 | S11: =S8/S5 -> 0.19557245 | U11: =U8/U5 -> 0.20194015 | W11: =W8/W5 -> 0.20257304 | Y11: =Y8/Y5 -> 0.19074541
O12: 2016 | P12: 予算 | Q12: =Q9/Q6 -> 0.15861642 | S12: =S9/S6 -> 0.17863397 | U12: =U9/U6 -> 0.20413483 | W12: =W9/W6 -> 0.20016156 | Y12: =Y9/Y6 -> 0.1867528
N14: ■在庫（実績/目標） | S14: （百万円） | U14: ■設備投資（予算） | AA14: （百万円）
N15: 原材料 | P15: 期首 | R15: 期末 | U15: 増産対応
N16: 貯蔵品 仕掛品 | P16: 16年3月末 | R16: 17年3月末 | U16: 生産性向上
N17: 完成品 商品 | U17: 品質改善
N18: 金額 | U18: その他
N19: 在庫日数 | U19: 合計 | Y19: =SUM(Y15:AB18) -> 0
C21: ■ | D21: =【データ入力】!H2 -> 2018年度 | H21: 結果 | P21: ■ | Q21: =【データ入力】!E2 -> 2018年度 | U21: 施策

Sheet 発表書式 (2)
C2: 部署名をご記載ください | P2: 実績： | Q2: =【データ入力】!H2 -> 2018年度 | U2: 予算： | V2: =【データ入力】!E2 -> 2018年度
C3: ■ 売上/利益 | AA3: 単位：百万円
Q4: 1Q | S4: 2Q | U4: 3Q | W4: 4Q | Y4: 通期 | AA4: 達成率/成長率
N5: 売上高 | O5: 2015 | P5: 実績 | Q5: =【データ入力】!O25 -> 1486.6295 | S5: =【データ入力】!P25 -> 1559.1618 | U5: =【データ入力】!Q25 -> 1576.2122 | W5: =【データ入力】!R25 -> 1539.1593 | Y5: =【データ入力】!U25 -> 6161.1627 | AA5: =【データ入力】!U25/【データ入力】!#REF! -> #REF!
O6: 2016 | P6: 予算 | Q6: =【データ入力】!O33 -> 1512.0345 | S6: =【データ入力】!P33 -> 1686.028 | U6: =【データ入力】!Q33 -> 1860.8454 | W6: =【データ入力】!R33 -> 1781.4062 | Y6: =【データ入力】!U33 -> 6840.3142
P7: 前期比 | Q7: =Q6/Q5 -> 1.017089 | S7: =SUM(【データ入力】!F33:H33) -> 1686.028 | U7: =SUM(【データ入力】!I33:K33) -> 1860.8454 | W7: =SUM(【データ入力】!L33:N33) -> 1781.4062 | Y7: =【データ入力】!U33 -> 6840.3142
N8: 営業利益 | O8: 2015 | P8: 実績 | Q8: =【データ入力】!O26 -> 240.19172 | S8: =【データ入力】!P26 -> 304.92909 | U8: =【データ入力】!Q26 -> 318.30052 | W8: =【データ入力】!R26 -> 311.79218 | Y8: =【データ入力】!U26 -> 1175.2135 | AA8: =【データ入力】!U26/【データ入力】!#REF! -> #REF!
O9: 2016 | P9: 予算 | Q9: =【データ入力】!O34 -> 239.83351 | S9: =【データ入力】!P34 -> 301.18188 | U9: =【データ入力】!Q34 -> 379.86337 | W9: =【データ入力】!R34 -> 356.56904 | Y9: =【データ入力】!U34 -> 1277.4478
P10: 前期比 | Q10: =Q9/Q8 -> 0.99850865 | S10: =S9/S8 -> 0.98771122 | U10: =U9/U8 -> 1.1934111 | W10: =W9/W8 -> 1.1436113 | Y10: =Y9/Y8 -> 1.0869921
N11: 営業 利益率 | O11: 2015 | P11: 実績 | Q11: =Q8/Q5 -> 0.16156798 | S11: =S8/S5 -> 0.19557245 | U11: =U8/U5 -> 0.20194015 | W11: =W8/W5 -> 0.20257304 | Y11: =Y8/Y5 -> 0.19074541
O12: 2016 | P12: 予算 | Q12: =Q9/Q6 -> 0.15861642 | S12: =S9/S6 -> 0.17863397 | U12: =U9/U6 -> 0.20413483 | W12: =W9/W6 -> 0.20016156 | Y12: =Y9/Y6 -> 0.1867528
C14: ■ | D14: =【データ入力】!H2 -> 2018年度 | H14: 結果 | P14: ■ | Q14: =【データ入力】!E2 -> 2018年度 | U14: 施策

Sheet 発表書式 (3)
C2: 部署名をご記載ください | P2: 実績： | Q2: =【データ入力】!H2 -> 2018年度 | U2: 予算： | V2: =【データ入力】!E2 -> 2018年度
C3: ■ 売上/利益 | AA3: 単位：百万円
Q4: 1Q | S4: 2Q | U4: 3Q | W4: 4Q | Y4: 通期 | AA4: 達成率/成長率
N5: 売上高 | O5: 2015 | P5: 実績 | Q5: =【データ入力】!O25 -> 1486.6295 | S5: =【データ入力】!P25 -> 1559.1618 | U5: =【データ入力】!Q25 -> 1576.2122 | W5: =【データ入力】!R25 -> 1539.1593 | Y5: =【データ入力】!U25 -> 6161.1627 | AA5: =【データ入力】!U25/【データ入力】!#REF! -> #REF!
O6: 2016 | P6: 予算 | Q6: =【データ入力】!O33 -> 1512.0345 | S6: =【データ入力】!P33 -> 1686.028 | U6: =【データ入力】!Q33 -> 1860.8454 | W6: =【データ入力】!R33 -> 1781.4062 | Y6: =【データ入力】!U33 -> 6840.3142
P7: 前期比 | Q7: =Q6/Q5 -> 1.017089 | S7: =S6/S5 -> 1.0813682 | U7: =U6/U5 -> 1.1805805 | W7: =W6/W5 -> 1.1573891 | Y7: =Y6/Y5 -> 1.1102311
N8: 営業利益 | O8: 2015 | P8: 実績 | Q8: =【データ入力】!O26 -> 240.19172 | S8: =【データ入力】!P26 -> 304.92909 | U8: =【データ入力】!Q26 -> 318.30052 | W8: =【データ入力】!R26 -> 311.79218 | Y8: =【データ入力】!U26 -> 1175.2135 | AA8: =【データ入力】!U26/【データ入力】!#REF! -> #REF!
O9: 2016 | P9: 予算 | Q9: =【データ入力】!O34 -> 239.83351 | S9: =【データ入力】!P34 -> 301.18188 | U9: =【データ入力】!Q34 -> 379.86337 | W9: =【データ入力】!R34 -> 356.56904 | Y9: =【データ入力】!U34 -> 1277.4478
P10: 前期比 | Q10: =Q9/Q8 -> 0.99850865 | S10: =S9/S8 -> 0.98771122 | U10: =U9/U8 -> 1.1934111 | W10: =W9/W8 -> 1.1436113 | Y10: =Y9/Y8 -> 1.0869921
N11: 営業 利益率 | O11: 2015 | P11: 実績 | Q11: =Q8/Q5 -> 0.16156798 | S11: =S8/S5 -> 0.19557245 | U11: =U8/U5 -> 0.20194015 | W11: =W8/W5 -> 0.20257304 | Y11: =Y8/Y5 -> 0.19074541
O12: 2016 | P12: 予算 | Q12: =Q9/Q6 -> 0.15861642 | S12: =S9/S6 -> 0.17863397 | U12: =U9/U6 -> 0.20413483 | W12: =W9/W6 -> 0.20016156 | Y12: =Y9/Y6 -> 0.1867528
N14: ■在庫（実績/目標） | R14: 単位：百万円 | U14: ■設備投資（予算） | AA14: 単位：百万円
N15: 原材料 | P15: 期首 | R15: 期末 | U15: 増産対応
N16: 貯蔵品 仕掛品 | P16: 16年3月末 | R16: 17年3月末 | U16: 生産性向上
N17: 完成品 商品 | U17: 品質改善
N18: 金額 | U18: その他
N19: 在庫日数 | U19: 合計 | Y19: =SUM(Y15:AB18) -> 0
C21: ■ | D21: =【データ入力】!H2 -> 2018年度 | H21: 結果 | P21: ■ | Q21: =【データ入力】!E2 -> 2018年度 | U21: 施策

Sheet 発表資料
O1: ２０１８年９月 フォーラム 第三部発表資料
C2: MARUWA(MALAYSA) | O2: アルミナ基板事業部 | AC2: 発表者：小川
C3: ■ 売上高/営業利益 | AB3: 単位： 百万円
P4: １Q | R4: ２Q | T4: ３Q | V4: ４Q | X4: 上期 | Z4: 下期 | AB4: 通期
N5: 売上高 | O5: 予算 | P5: =【データ入力】!O25 -> 1486.6295 | R5: =【データ入力】!P25 -> 1559.1618 | T5: =【データ入力】!Q25 -> 1576.2122 | V5: =【データ入力】!R25 -> 1539.1593 | X5: =【データ入力】!S25 -> 3045.7913 | Z5: =【データ入力】!T25 -> 3115.3714 | AB5: =【データ入力】!U25 -> 6161.1627
O6: 実/見込 | P6: =【データ入力】!O33 -> 1512.0345 | R6: =【データ入力】!P33 -> 1686.028 | T6: =【データ入力】!Q33 -> 1860.8454 | V6: =【データ入力】!R33 -> 1781.4062 | X6: =【データ入力】!S33 -> 3198.0626 | Z6: =【データ入力】!T33 -> 3642.2516 | AB6: =【データ入力】!U33 -> 6840.3142
O7: 予算比 | P7: =P6/P5 -> 1.017089 | R7: =R6/R5 -> 1.0813682 | T7: =T6/T5 -> 1.1805805 | V7: =V6/V5 -> 1.1573891 | X7: =X6/X5 -> 1.049994 | Z7: =Z6/Z5 -> 1.1691227 | AB7: =AB6/AB5 -> 1.1102311
N8: 営業利益 | O8: 予算 | P8: =【データ入力】!O26 -> 240.19172 | R8: =【データ入力】!P26 -> 304.92909 | T8: =【データ入力】!Q26 -> 318.30052 | V8: =【データ入力】!R26 -> 311.79218 | X8: =【データ入力】!S26 -> 545.12081 | Z8: =【データ入力】!T26 -> 630.0927 | AB8: =【データ入力】!U26 -> 1175.2135
O9: 実/見込 | P9: =【データ入力】!O34 -> 239.83351 | R9: =【データ入力】!P34 -> 301.18188 | T9: =【データ入力】!Q34 -> 379.86337 | V9: =【データ入力】!R34 -> 356.56904 | X9: =【データ入力】!S34 -> 541.01539 | Z9: =【データ入力】!T34 -> 736.43241 | AB9: =【データ入力】!U34 -> 1277.4478
O10: 予算比 | P10: =P9/P8 -> 0.99850865 | R10: =R9/R8 -> 0.98771122 | T10: =T9/T8 -> 1.1934111 | V10: =V9/V8 -> 1.1436113 | X10: =X9/X8 -> 0.9924688 | Z10: =Z9/Z8 -> 1.1687684 | AB10: =AB9/AB8 -> 1.0869921
N11: 営業 利益率 | O11: 予算 | P11: =P8/P5 -> 0.16156798 | R11: =R8/R5 -> 0.19557245 | T11: =T8/T5 -> 0.20194015 | V11: =V8/V5 -> 0.20257304 | X11: =X8/X5 -> 0.1789751 | Z11: =Z8/Z5 -> 0.20225283 | AB11: =AB8/AB5 -> 0.19074541
O12: 実/見込 | P12: =P9/P6 -> 0.15861642 | R12: =R9/R6 -> 0.17863397 | T12: =T9/T6 -> 0.20413483 | V12: =V9/V6 -> 0.20016156 | X12: =X9/X6 -> 0.16916973 | Z12: =Z9/Z6 -> 0.20219152 | AB12: =AB9/AB6 -> 0.1867528
C14: ■ | D14: 上期結果 | P14: ■ | Q14: 下期施策
C15: ■ 収益貢献製品・商品/市場状況/競争状況 | P15: ■ 収益貢献製品・商品、ターゲット市場/懸念事項
C17: チップ抵抗・・・品不足の影響もあり売り手市場の状態 | Q17: ジルコニア基板の顧客増産対応に伴い受注確保 | Z17: 150k→250k/M
D18: 基板価格見直し 3月対比 10%値上げ | R18: （新規設備反直炉 12月末稼動予定）
D19: 競合増産 基板全体占有率 三環 50% MARUWA 15% | Q19: チップ基板価格見直し ９月対比 10%値上げ
C20: 大型基板・・・DBC用基板調整、LED用基板受注増
C21: 材料費 ８％UP、電動費 ５％UP、資材品での価格UP | Q21: 労務費（最低賃金の上昇）５％UP 2019年1月より
C23: ■ 在庫状況（18年3月末 → 18年9月末見込み） | P23: ■ 在庫削減への取組み（削減目標）
C24: 在庫回転日数 3月末 59日 → 9月末 41日 | Q24: 在庫回転日数 ２０１９年３月末 40日
C26: ■ 取組み結果（収益効果策、新製品・商品/新市場、トピックス等） | P26: ■ 収益取組み項目（見込効果、スケジュール）、収益強化策等
C27: 労務費削減 ３月末対比 １５名削減 | Q27: 外観自動検査機導入 労務費削減 20名（２０１９年1月）
C28: 歩留まり改善目標未達 SUB 目標81.0% → 80.5％ | Q28: 歩留まり改善スピードUP 技術メンバー常駐（2018年10月 2名）
C29: TPH 目標80.4％ → 73.9％(ZTA) | Q29: 顧客クレーム低減活動 2018年下期 13件（上期50％down）
C30: 顧客クレーム増加（SUB） 2018年上期 26件 （前期１４件） | Q30: 工程異常処理及び設備管理基準のルール強化

Sheet 実績見込予算
E1: 27.65
A2: アルミナ基板連結予実管理 | G2: 予算集計 | J2: 単位：千円
B3: 管理会計 | E3: 実績 | F3: 実績 | G3: 実績 | H3: 実績 | I3: 実績 | J3: 見込 | K3: 下期予算 | L3: 下期予算 | M3: 下期予算 | N3: 下期予算 | O3: 下期予算 | P3: 下期予算 | U3: 単位：千円 | X3: 単位：千円 | AB3: 単位：千円 | AC3: 単位：千円
A4: PRODUCTION PROFIT | E4: 41729 | F4: 41759 | G4: 41790 | H4: 41820 | I4: 41851 | J4: 41882 | K4: 41912 | L4: 41943 | M4: 41973 | N4: 42004 | O4: 42035 | P4: 42063 | R4: 1Q | S4: 2Q | T4: 3Q | U4: 4Q | W4: 上期 | X4: 下期 | Z4: 2015 | AA4: 2016 | AB4: 2017 | AC4: 2018 | AD4: 予算増減
A5: チップJM | C5: 外部売上 | D5: 期初予算 | E5: 0 | F5: 0 | G5: 0 | H5: 0 | I5: 0 | J5: 0 | K5: 0 | L5: 0 | M5: 0 | N5: 0 | O5: 0 | P5: 0 | R5: 0 | S5: 0 | T5: 0 | U5: 0 | W5: 0 | X5: 0 | Z5: 0 | AA5: 0 | AB5: 0 | AC5: 0
D6: 実績値 | E6: 0 | F6: 0 | G6: 0 | R6: 0 | S6: 0 | T6: 0 | U6: 0 | W6: 0 | X6: 0 | Z6: -8622.5345 | AA6: 975.138 | AB6: 300.38 | AC6: 0
C7: 営業利益 | D7: 期初予算 | E7: 0 | F7: 0 | G7: 0 | H7: 0 | I7: 0 | J7: 0 | K7: 0 | L7: 0 | M7: 0 | N7: 0 | O7: 0 | P7: 0 | R7: 0 | S7: 0 | T7: 0 | U7: 0 | W7: 0 | X7: 0 | Z7: 0 | AA7: 0 | AB7: 0 | AC7: 0
D8: 実績値 | E8: 0 | F8: 0 | G8: 0 | R8: 0 | S8: 0 | T8: 0 | U8: 0 | W8: 0 | X8: 0 | Z8: -13435.73 | AA8: 239.91642 | AB8: -955.147 | AC8: 0
A9: チップ商品+HIC | C9: 外部売上 | D9: 期初予算 | E9: 44927.775 | F9: 45091.975 | G9: 45782.775 | H9: 44991.975 | I9: 44542.055 | J9: 45511.975 | K9: 46689.18 | L9: 45686.975 | M9: 45037.055 | N9: 46476.975 | O9: 45602.055 | P9: 46476.975 | R9: 135802.52 | S9: 135046.01 | T9: 137413.21 | U9: 138556.01 | W9: 270848.53 | X9: 275969.21 | Z9: 0 | AA9: 670553.44 | AB9: 475365.6 | AC9: 546817.74
D10: 実績値 | E10: 52985.223 | F10: 43235.188 | G10: 53392.121 | H10: 56557.742 | I10: 44047.638 | J10: 45511.975 | K10: 46267.295 | L10: 46235.215 | M10: 52557.835 | N10: 49590.165 | O10: 52192.285 | P10: 52355.165 | R10: 149612.53 | S10: 146117.36 | T10: 145060.35 | U10: 154137.61 | W10: 295729.89 | X10: 299197.96 | Z10: 666844.18 | AA10: 562499.87 | AB10: 596657.66 | AC10: 594927.85
C11: 営業利益 | D11: 期初予算 | E11: -8910.0642 | F11: -8901.8542 | G11: -8867.3142 | H11: -6875 | I11: -6875 | J11: -8880.8542 | K11: -8821.994 | L11: -8872.1042 | M11: -8904.6002 | N11: -8832.6042 | O11: -8876.3502 | P11: -8832.6042 | R11: -26679.233 | S11: -22630.854 | T11: -26598.698 | U11: -26541.559 | W11: -49310.087 | X11: -53140.257 | Z11: 0 | AA11: -61004.736 | AB11: -54695.16 | AC11: -102450.34
D12: 実績値 | E12: -7736.395 | F12: -9231.928 | G12: -5002.934 | H12: -7486.984 | I12: -6827.201 | J12: -6593 | K12: -6593 | L12: -6593 | M12: -6593 | N12: -6593 | O12: -6593 | P12: -6593 | R12: -21971.257 | S12: -20907.185 | T12: -19779 | U12: -19779 | W12: -42878.442 | X12: -39558 | Z12: -91670.585 | AA12: -90297.085 | AB12: -82105.129 | AC12: -82436.442
A13: チップMM | C13: 外部売上 | D13: 期初予算 | E13: 305888.85 | F13: 307110.85 | G13: 304786.85 | H13: 324635.61 | I13: 326192.26 | J13: 323863.26 | K13: 326529.76 | L13: 332113.26 | M13: 330927.76 | N13: 315725.78 | O13: 319343.15 | P13: 318131.77 | R13: 917786.55 | S13: 974691.13 | T13: 989570.78 | U13: 953200.7 | W13: 1892477.7 | X13: 1942771.5 | Z13: 0 | AA13: 3232944.9 | AB13: 3236670.3 | AC13: 3835249.2
D14: 実績値 | E14: 293300.39 | F14: 305618.27 | G14: 289163.18 | H14: 323741.68 | I14: 334377.78 | J14: 327885.28 | K14: 340579.85 | L14: 341994.92 | M14: 339171.84 | N14: 331484.81 | O14: 324257.35 | P14: 323511.23 | R14: 888081.84 | S14: 986004.74 | T14: 1021746.6 | U14: 979253.38 | W14: 1874086.6 | X14: 2001000 | Z14: 2616865.2 | AA14: 2922223.8 | AB14: 2952301.3 | AC14: 3924464.1
C15: 内部売上 | D15: 期初予算 | E15: 41319.352 | F15: 41014.592 | G15: 41319.352 | H15: 40919.592 | I15: 41414.352 | J15: 41413.592 | K15: 42577.271 | L15: 41082.992 | M15: 41387.752 | N15: 41025.992 | O15: 41520.752 | P15: 41025.992 | R15: 123653.3 | S15: 123747.54 | T15: 125048.02 | U15: 123572.74 | Z15: 0 | AA15: 0 | AB15: 368458.19 | AC15: 496021.59
D16: 実績値 | E16: 45454.656 | F16: 46776.6 | G16: 40247.625 | H16: 36475.063 | I16: 41938.799 | J16: 41413.592 | K16: 42013.194 | L16: 42362.718 | M16: 48576.478 | N16: 45202.696 | O16: 48229.206 | P16: 47829.446 | R16: 132478.88 | S16: 119827.45 | T16: 132952.39 | U16: 141261.35 | Z16: 534952.68 | AA16: 495681.03 | AB16: 512705.14 | AC16: 526520.07
C17: 営業利益 | D17: 期初予算 | E17: 61743.929 | F17: 65333.251 | G17: 55700.489 | H17: 78838.731 | I17: 79108.432 | J17: 76457.649 | K17: 84484.595 | L17: 86544.26 | M17: 83145.116 | N17: 80952.156 | O17: 82695.113 | P17: 82147.605 | R17: 182777.67 | S17: 234404.81 | T17: 254173.97 | U17: 245794.87 | W17: 417182.48 | X17: 499968.85 | Z17: 0 | AA17: 324026.45 | AB17: 574088.07 | AC17: 917151.33
D18: 実績値 | E18: 49105.037 | F18: 53876.303 | G18: 49140.354 | H18: 59446.95 | I18: 61932.498 | J18: 52075.79 | K18: 69921.16 | L18: 66936.99 | M18: 71301.24 | N18: 69372.28 | O18: 65571.74 | P18: 70794.09 | R18: 152121.69 | S18: 173455.24 | T18: 208159.39 | U18: 205738.11 | W18: 325576.93 | X18: 413897.5 | Z18: 30230.706 | AA18: 403871.74 | AB18: 487653.73 | AC18: 728289.89
A19: チップ連結 | C19: 外部売上 | D19: 期初予算 | E19: 350816.63 | F19: 352202.83 | G19: 350569.63 | H19: 369627.59 | I19: 370734.32 | J19: 369375.24 | K19: 373218.94 | L19: 377800.24 | M19: 375964.82 | N19: 362202.76 | O19: 364945.2 | P19: 364608.75 | R19: 1053589.1 | S19: 1109737.1 | T19: 1126984 | U19: 1091756.7 | W19: 2163326.2 | X19: 2218740.7 | Z19: 0 | AA19: 3417875.8 | AB19: 3712035.9 | AC19: 4382066.9
D20: 実績値 | E20: 346285.61 | F20: 348853.45 | G20: 342555.3 | H20: 380299.43 | I20: 378425.42 | J20: 373397.25 | K20: 386847.15 | L20: 388230.13 | M20: 391729.68 | N20: 381074.97 | O20: 376449.63 | P20: 375866.4 | R20: 1037694.4 | S20: 1132122.1 | T20: 1166807 | U20: 1133391 | V20: 1.0030001 | W20: 2169816.5 | X20: 2300198 | Y20: 0.94455051 | Z20: 3275086.9 | AA20: 3485698.8 | AB20: 3549259.3 | AC20: 4519391.9
C21: 営業利益 | D21: 期初予算 | E21: 52833.864 | F21: 56431.397 | G21: 46833.175 | H21: 71963.731 | I21: 72233.432 | J21: 67576.795 | K21: 75662.601 | L21: 77672.156 | M21: 74240.516 | N21: 72119.552 | O21: 73818.763 | P21: 73315.001 | R21: 156098.44 | S21: 211773.96 | T21: 227575.27 | U21: 219253.32 | W21: 367872.39 | X21: 446828.59 | Z21: 0 | AA21: 244947.16 | AB21: 519392.91 | AC21: 814700.98
D22: 実績値 | E22: 41368.641 | F22: 44644.375 | G22: 44137.42 | H22: 51959.966 | I22: 55105.297 | J22: 45482.79 | K22: 63328.16 | L22: 60343.99 | M22: 64708.24 | N22: 62779.28 | O22: 58978.74 | P22: 64201.09 | R22: 130150.44 | S22: 152548.05 | T22: 188380.39 | U22: 185959.11 | W22: 282698.49 | X22: 374339.5 | Y22: 0.70367703 | Z22: -74875.609 | AA22: 313814.57 | AB22: 404593.46 | AC22: 645853.45
D23: 利益率 | E23: 0.11946393 | F23: 0.12797458 | G23: 0.12884757 | H23: 0.13662909 | I23: 0.14561733 | J23: 0.12180805 | K23: 0.16370331 | L23: 0.15543356 | M23: 0.16518595 | N23: 0.1647426 | O23: 0.156671 | P23: 0.17080827 | R23: 0.14815875 | S23: 0.19083254 | T23: 0.20193301 | U23: 0.20082617 | W23: 0.17004943 | X23: 0.20138838 | Z23: -0.35910326 | AA23: 1.0774259 | AB23: 0.1399213 | AC23: 1.7083194
A24: 大型基板MM | C24: 外部売上 | D24: 期初予算 | E24: 132526.39 | F24: 154076.27 | G24: 146437.74 | H24: 150904.03 | I24: 143869.36 | J24: 154651.29 | K24: 152369.53 | L24: 151521.54 | M24: 145337.11 | N24: 151090.68 | O24: 147312.76 | P24: 148999.14 | R24: 433040.4 | S24: 449424.68 | T24: 449228.17 | U24: 447402.58 | W24: 882465.08 | X24: 896630.75 | Z24: 0 | AA24: 1484951.9 | AB24: 1608163.4 | AC24: 1779095.8
D25: 実績値 | E25: 153556.11 | F25: 156091.94 | G25: 164692.13 | H25: 175190.03 | I25: 170016.27 | J25: 208699.64 | K25: 232998.55 | L25: 234661.49 | M25: 226378.39 | N25: 214249.83 | O25: 216683.6 | P25: 217081.81 | R25: 474340.18 | S25: 553905.94 | T25: 694038.44 | U25: 648015.23 | W25: 1028246.1 | X25: 1342053.7 | Z25: 1356485 | AA25: 1549762.5 | AB25: 1926616.7 | AC25: 2421897.1
C26: 内部売上 | D26: 期初予算 | E26: 1362.034 | F26: 1822.784 | G26: 2174.284 | H26: 1822.784 | I26: 900.6 | J26: 1822.784 | K26: 1777.45 | L26: 2319.634 | M26: 1397.45 | N26: 3127.134 | O26: 1801.2 | P26: 3127.134 | R26: 5359.102 | S26: 4546.168 | T26: 5494.534 | U26: 8055.468 | Z26: 0 | AA26: 0 | AB26: 8827.573 | AC26: 23455.272
D27: 実績値 | E27: 487.85739 | F27: 1040.325 | G27: 151.93778 | H27: 927.061 | I27: 2910.253 | J27: 1822.784 | K27: 2042.88 | L27: 1642.88 | M27: 1424.7 | N27: 2008.38 | O27: 1424.7 | P27: 2008.38 | R27: 1680.1202 | S27: 5660.098 | T27: 5110.46 | U27: 5441.46 | W27: 7340.2182 | X27: 10551.92 | Z27: 44009 | AA27: 32383 | AB27: 13073.06 | AC27: 17892.138
C28: 営業利益 | D28: 期初予算 | E28: 21898.885 | F28: 33116.849 | G28: 29077.549 | H28: 31857.185 | I28: 27910.409 | J28: 33387.539 | K28: 31002.626 | L28: 32194.398 | M28: 27528.228 | N28: 31981.959 | O28: 30009.397 | P28: 30547.504 | R28: 84093.282 | S28: 93155.133 | T28: 90725.251 | U28: 92538.861 | W28: 177248.41 | X28: 183264.11 | Z28: 0 | AA28: 433172.87 | AB28: 461044.87 | AC28: 360512.53
D29: 実績値 | E29: 34066.443 | F29: 34268.517 | G29: 41348.112 | H29: 47341.83 | I29: 45915.581 | J29: 55376.421 | K29: 64971.588 | L29: 66280.217 | M29: 60231.171 | N29: 55581.82 | O29: 57410.193 | P29: 57617.921 | R29: 109683.07 | S29: 148633.83 | T29: 191482.98 | U29: 170609.93 | W29: 258316.9 | X29: 362092.91 | Z29: 421618.58 | AA29: 476924.21 | AB29: 517417.63 | AC29: 659615.97 | AD29: 1.1222718
D30: 利益率 | E30: 0.22114753 | F30: 0.21808708 | G30: 0.25083167 | H30: 0.26880883 | I30: 0.26552075 | J30: 0.26304286 | K30: 0.27642611 | L30: 0.28048663 | M30: 0.26440014 | N30: 0.25701601 | O30: 0.26321874 | P30: 0.26298723 | R30: 0.19181883 | S30: 0.20520069 | T30: 0.19951775 | U30: 0.20317757 | W30: 0.20085601 | X30: 0.20439196 | Z30: 3.64395 | AA30: 3.7005901 | AB30: 0.2851252 | AC30: 3.2037974
A31: ｱﾙﾐﾅ基板 TOTAL | C31: 外部売上 | D31: 期初予算 | E31: 483343.02 | F31: 506279.1 | G31: 497007.37 | H31: 520531.62 | I31: 514603.67 | J31: 524026.53 | K31: 525588.47 | L31: 529321.78 | M31: 521301.92 | N31: 513293.44 | O31: 512257.96 | P31: 513607.89 | R31: 1486629.5 | S31: 1559161.8 | T31: 1576212.2 | U31: 1539159.3 | W31: 3045791.3 | X31: 3115371.4 | Z31: 0 | AA31: 4902827.7 | AB31: 5320199.4 | AC31: 6161162.7
D32: 実績値 | E32: 499841.72 | F32: 504945.39 | G32: 507247.43 | H32: 555489.46 | I32: 548441.69 | J32: 582096.89 | K32: 619845.7 | L32: 622891.62 | M32: 618108.07 | N32: 595324.8 | O32: 593133.23 | P32: 592948.2 | R32: 1512034.5 | S32: 1686028 | T32: 1860845.4 | U32: 1781406.2 | W32: 3198062.6 | X32: 3642251.6 | Z32: 4631571.9 | AA32: 5035461.3 | AB32: 5475876 | AC32: 6941289.1
C33: 営業利益 | D33: 期初予算 | E33: 74732.749 | F33: 89548.246 | G33: 75910.724 | H33: 103820.92 | I33: 100143.84 | J33: 100964.33 | K33: 106665.23 | L33: 109866.55 | M33: 101768.74 | N33: 104101.51 | O33: 103828.16 | P33: 103862.5 | R33: 240191.72 | S33: 304929.09 | T33: 318300.52 | U33: 311792.18 | W33: 545120.81 | X33: 630092.7 | Z33: 0 | AA33: 678120.03 | AB33: 980437.78 | AC33: 1175213.5
D34: 実績値 | E34: 75435.085 | F34: 78912.892 | G34: 85485.532 | H34: 99301.796 | I34: 101020.88 | J34: 100859.21 | K34: 128299.75 | L34: 126624.21 | M34: 124939.41 | N34: 118361.1 | O34: 116388.93 | P34: 121819.01 | R34: 239833.51 | S34: 301181.88 | T34: 379863.37 | U34: 356569.04 | W34: 541015.39 | X34: 736432.41 | Z34: 346742.97 | AA34: 790738.78 | AB34: 922011.09 | AC34: 1305469.4
D36: 予算 | E36: =+E33/E31 -> 0.15461638 | F36: =+F33/F31 -> 0.17687526 | G36: =+G33/G31 -> 0.15273561 | H36: =+H33/H31 -> 0.1994517 | I36: =+I33/I31 -> 0.19460382 | J36: =+J33/J31 -> 0.19267027 | K36: =+K33/K31 -> 0.20294438 | L36: =+L33/L31 -> 0.20756099 | ... X36: =+X33/X31 -> 0.20225283 | AB36: 0.18428591 | AC36: 0.19074541
D37: 実績値 | E37: =+E34/E32 -> 0.15091794 | F37: =+F34/F32 -> 0.15628005 | G37: =+G34/G32 -> 0.16852827 | H37: =+H34/H32 -> 0.1787645 | I37: =+I34/I32 -> 0.18419621 | J37: =+J34/J32 -> 0.17326877 | K37: =+K34/K32 -> 0.20698659 | L37: =+L34/L32 -> 0.20328449 | ... X37: =+X34/X32 -> 0.20219152 | AB37: 0.16837691 | AC37: -0.028441203
X39: 0.20684533
E40: 43191 | F40: 43221 | G40: 43252 | H40: 43282 | I40: 43313 | J40: 43344 | K40: 43374 | L40: 43405 | M40: 43435 | N40: 43466 | O40: 43497 | P40: 43525
A41: ﾊﾞﾙﾌﾞ | C41: 外部売上 | D41: 期初予算 | E41: 33836 | F41: 34523 | G41: 34509 | H41: 33803 | I41: 33824 | J41: 34011 | K41: 33449 | L41: 38592 | M41: 35024 | N41: 36422 | O41: 34571 | P41: 35419 | R41: 102868 | S41: 101638 | T41: 107065 | U41: 106412 | W41: 204506 | X41: 213477 | Z41: 0 | AA41: 444116 | AB41: 391744.75 | AC41: 417983
D42: 実績値 | E42: 40531.811 | F42: 42072.565 | G42: 40174.258 | H42: 43802.345 | I42: 41958.693 | J42: 41958.693 | K42: 37926.601 | L42: 38592 | M42: 35024 | N42: 36422 | O42: 34571 | P42: 35419 | R42: 122778.63 | S42: 127719.73 | T42: 111542.6 | U42: 106412 | W42: 250498.37 | X42: 217954.6 | Z42: 0 | AA42: 387831.74 | AB42: 417809.65 | AC42: 468452.97
...

Sheet Sheet3

Sheet Sheet1
